2020-07-30  15:27:56 Thu  run_spiders.py [line:41] ERROR: No connection adapters were found for '['https://www.dieniao.com/FreeProxy/1.html', 'https://www.dieniao.com/FreeProxy/2.html']'
Traceback (most recent call last):
  File "/home/xqh/桌面/IPProxyPool/core/proxy_spider/run_spiders.py", line 36, in __execute_one_spider_task
    for proxy in spider.get_proxies():
  File "/home/xqh/桌面/IPProxyPool/core/proxy_spider/base_spider.py", line 41, in get_proxies
    page = self.get_page_from_url(url)
  File "/home/xqh/桌面/IPProxyPool/core/proxy_spider/base_spider.py", line 23, in get_page_from_url
    response = requests.get(url, headers=get_request_headers())
  File "/usr/local/lib/python3.6/dist-packages/requests/api.py", line 75, in get
    return request('get', url, params=params, **kwargs)
  File "/usr/local/lib/python3.6/dist-packages/requests/api.py", line 60, in request
    return session.request(method=method, url=url, **kwargs)
  File "/usr/local/lib/python3.6/dist-packages/requests/sessions.py", line 533, in request
    resp = self.send(prep, **send_kwargs)
  File "/usr/local/lib/python3.6/dist-packages/requests/sessions.py", line 640, in send
    adapter = self.get_adapter(url=request.url)
  File "/usr/local/lib/python3.6/dist-packages/requests/sessions.py", line 731, in get_adapter
    raise InvalidSchema("No connection adapters were found for '%s'" % url)
requests.exceptions.InvalidSchema: No connection adapters were found for '['https://www.dieniao.com/FreeProxy/1.html', 'https://www.dieniao.com/FreeProxy/2.html']'
2020-07-30  15:27:57 Thu  run_spiders.py [line:41] ERROR: 'utf-8' codec can't decode byte 0xb4 in position 187: invalid start byte
Traceback (most recent call last):
  File "/home/xqh/桌面/IPProxyPool/core/proxy_spider/run_spiders.py", line 36, in __execute_one_spider_task
    for proxy in spider.get_proxies():
  File "/home/xqh/桌面/IPProxyPool/core/proxy_spider/base_spider.py", line 41, in get_proxies
    page = self.get_page_from_url(url)
  File "/home/xqh/桌面/IPProxyPool/core/proxy_spider/base_spider.py", line 24, in get_page_from_url
    return response.content.decode()
UnicodeDecodeError: 'utf-8' codec can't decode byte 0xb4 in position 187: invalid start byte
2020-07-30  15:35:39 Thu  run_spiders.py [line:41] ERROR: No connection adapters were found for '['https://www.dieniao.com/FreeProxy/1.html', 'https://www.dieniao.com/FreeProxy/2.html']'
Traceback (most recent call last):
  File "/home/xqh/桌面/IPProxyPool/core/proxy_spider/run_spiders.py", line 36, in __execute_one_spider_task
    for proxy in spider.get_proxies():
  File "/home/xqh/桌面/IPProxyPool/core/proxy_spider/base_spider.py", line 41, in get_proxies
    page = self.get_page_from_url(url)
  File "/home/xqh/桌面/IPProxyPool/core/proxy_spider/base_spider.py", line 23, in get_page_from_url
    response = requests.get(url, headers=get_request_headers())
  File "/usr/local/lib/python3.6/dist-packages/requests/api.py", line 75, in get
    return request('get', url, params=params, **kwargs)
  File "/usr/local/lib/python3.6/dist-packages/requests/api.py", line 60, in request
    return session.request(method=method, url=url, **kwargs)
  File "/usr/local/lib/python3.6/dist-packages/requests/sessions.py", line 533, in request
    resp = self.send(prep, **send_kwargs)
  File "/usr/local/lib/python3.6/dist-packages/requests/sessions.py", line 640, in send
    adapter = self.get_adapter(url=request.url)
  File "/usr/local/lib/python3.6/dist-packages/requests/sessions.py", line 731, in get_adapter
    raise InvalidSchema("No connection adapters were found for '%s'" % url)
requests.exceptions.InvalidSchema: No connection adapters were found for '['https://www.dieniao.com/FreeProxy/1.html', 'https://www.dieniao.com/FreeProxy/2.html']'
2020-07-30  17:28:54 Thu  run_spiders.py [line:42] ERROR: 127.0.0.1:27017: [Errno 111] Connection refused
Traceback (most recent call last):
  File "/home/xqh/桌面/IPProxyPool/core/proxy_spider/run_spiders.py", line 40, in __execute_one_spider_task
    self.mongo_pool.insert_one(proxy)
  File "/home/xqh/桌面/IPProxyPool/core/db/mongo_pool.py", line 22, in insert_one
    count = self.proxies.count_documents({'_id': proxy.ip})
  File "/usr/local/lib/python3.6/dist-packages/pymongo/collection.py", line 1721, in count_documents
    _cmd, self._read_preference_for(session), session)
  File "/usr/local/lib/python3.6/dist-packages/pymongo/mongo_client.py", line 1454, in _retryable_read
    read_pref, session, address=address)
  File "/usr/local/lib/python3.6/dist-packages/pymongo/mongo_client.py", line 1253, in _select_server
    server = topology.select_server(server_selector)
  File "/usr/local/lib/python3.6/dist-packages/pymongo/topology.py", line 235, in select_server
    address))
  File "/usr/local/lib/python3.6/dist-packages/pymongo/topology.py", line 193, in select_servers
    selector, server_timeout, address)
  File "/usr/local/lib/python3.6/dist-packages/pymongo/topology.py", line 209, in _select_servers_loop
    self._error_message(selector))
pymongo.errors.ServerSelectionTimeoutError: 127.0.0.1:27017: [Errno 111] Connection refused
